Workbook
Name dieu_phuluc13: 'HĐLĐ'!$A$112

Sheet DANH SÁCH
B1: CÔNG TY TNHH ĐÀO TẠO VÀ CUNG ỨNG NHÂN LỰC NHẬT TÂN
B2: Số 8 TX01, Phường Thới An, Tp Hồ Chí Minh
B8: STT | C8: Số hợp đồng | D8: Ngày hợp đồng | E8: Danh xưng | F8: Tên | G8: Giới tính | H8: Ngày tháng năm sinh | I8: CCCD/CMND | J8: Ngày Cấp | K8: Nơi cấp | L8: Số Hộ Chiếu | M8: Ngày cấp | N8: SĐT Học Viên | O8: Người thân | P8: Quan hệ | Q8: SĐT Người thân | R8: Ngày đậu PV | S8: Ngày bay dự kiến | T8: Địa chỉ | U8: Nghiệp đoàn | V8: Công ty | W8: Công việc | X8: Địa chỉ công ty | Y8: Giám đốc | Z8: SĐT Cty tiếp nhận | AA8: Mức trợ cấp đào tạo | AB8: Tiền lương | AC8: Thuế | AD8: BHXH | AE8: Tiền thuê nhà | AH8: Ghi Chú | AI8: PT
B9: (1) | C9: (2) | D9: (3) | E9: (4) | F9: (5) | G9: (6) | H9: (7) | I9: (8) | J9: (9) | K9: (10) | L9: (11) | M9: (12) | N9: (13) | O9: (14) | P9: (15) | Q9: (16) | R9: (17) | S9: (18) | T9: (19) | U9: (20) | V9: (21) | W9: (22) | X9: (23) | Y9: (24) | Z9: (25) | AA9: (26) | AB9: (27) | AC9: (28) | AD9: (29) | AE9: (30)
B10: =ROW()-9

Sheet HĐLĐ
K1: Mẫu số 03
A2: CỘNG HÒA XÃ HỘI CHỦ NGHĨA VIỆT NAM Độc Lập- Tự Do- Hạnh Phúc …o0o… | L2: 1
A3: HỢP ĐỒNG ĐƯA NGƯỜI LAO ĐỘNG ĐI LÀM VIỆC Ở NƯỚC NGOÀI
A4: (Ban hành kèm theo Thông tư số 09/2026/TT – BNV ngày 15/05/2026 của Bộ Nội Vụ)
A5: ="Số"&":"& " " & VLOOKUP($L$2,'DANH SÁCH'!$B$8:$AH$70,2,0)
A8: ="Hôm nay, ngày" &" " & DAY('DANH SÁCH'!D10) &" " & "tháng" &" "& MONTH('DANH SÁCH'!D10)& " " & " năm" &" "& YEAR('DANH SÁCH'!D10) &", tại Công Ty TNHH Đào Tạo Và Cung Ứng Nhân Lực Nhật Tân, chúng tôi gồm:"
A10: Bên đưa đi: CÔNG TY TNHH ĐÀO TẠO VÀ CUNG ỨNG NHÂN LỰC NHẬT TÂN (NHATTAN MANPOWER)
A11: - Địa chỉ: Số 8 TX01, Phường Thới An, Tp. Hồ Chí Minh.
A12: - Điện thoại: 028 6274 5444
A13: - E-mail: nhattan@nhattangroup.vn
A14: - Địa chỉ trang thông tin điện tử: nhattangroup.vn
A15: - Người đại diện theo pháp luật của doanh nghiệp: NGUYỄN KHẮC QUANG HUY
A16: - Chức vụ: Giám Đốc
A18: Và
A19: ="-"&" "&VLOOKUP($L$2,'DANH SÁCH'!$B$8:$AH$70,4,0)&" "&VLOOKUP(HĐLĐ!$L$2,'DANH SÁCH'!$B$8:$AH$70,5,0)&" " & "(sau đây gọi là Người lao động)"
A20: - Ngày tháng năm sinh: | D20: =VLOOKUP($L$2,'DANH SÁCH'!$B$8:$AH$70,7,0) | G20: Giới tính: | H20: =VLOOKUP($L$2,'DANH SÁCH'!$B$8:$AH$70,6,0)
A21: - Địa chỉ thường trú: | C21: =VLOOKUP($L$2,'DANH SÁCH'!B8:AH70,19,0)
A22: - Số CCCD/ĐDCN: | C22: =VLOOKUP($L$2,'DANH SÁCH'!$B$8:$AH$70,8,0) | G22: Ngày cấp: | H22: =VLOOKUP($L$2,'DANH SÁCH'!$B$8:$AH$70,9,0)
A23: ="Nơi cấp:"&" "&VLOOKUP($L$2,'DANH SÁCH'!$B$8:$AH$70,10,0)
A24: - Số Hộ chiếu: | B24: =VLOOKUP($L$2,'DANH SÁCH'!B8:AH70,11,0) | E24: Ngày cấp: | F24: =VLOOKUP($L$2,'DANH SÁCH'!$B$8:$AH$70,12,0) | H24: Nơi cấp: Cục Quản Lý Xuất Nhập Cảnh
A25: - Người được báo tin: | D25: =VLOOKUP($L$2,'DANH SÁCH'!$B$8:$AH$70,14,0) | G25: Số điện thoại: | H25: =VLOOKUP($L$2,'DANH SÁCH'!$B$8:$AH$70,16,0)
A26: Mối quan hệ với người lao động: | E26: =VLOOKUP($L$2,'DANH SÁCH'!$B$8:$AH$70,15,0)
A27: - Địa chỉ báo tin tại Việt Nam: | E27: =VLOOKUP($L$2,'DANH SÁCH'!$B$8:$AH$70,19,0)
A28: =" Căn cứ vào Hợp đồng cung ứng lao động ngày 27/06/2024 ký giữa Công Ty TNHH Đào Tạo Và Cung Ứng Nhân Lực Nhật Tân với" &" "& VLOOKUP($L$2,'DANH SÁCH'!$B$8:$AH$70,20,0) &" " &"và thông báo việc người lao động đã trúng tuyển đi làm việc ở nước ngoài ngày" &" "&DAY('DANH SÁCH'!R10)& " "&"tháng"&" "&MONTH('DANH SÁCH'!R10)&" "&"năm"&" "&YEAR('DANH SÁCH'!R10)&"."
A29: Hai Bên thoả thuận và ký kết thực hiện các điều khoản hợp đồng sau đây:
A30: Điều 1: Điều khoản chung
A31: - Thời hạn của hợp đồng lao động: 03 năm 0 tháng 0 ngày ( tính từ ngày người lao động nhập cảnh vào Nhật Bản.)
A32: - Ngành, nghề, công việc : | D32: =VLOOKUP($L$2,'DANH SÁCH'!$B$8:$AH$70,22,0)
A33: - Địa điểm làm việc: | C33: =VLOOKUP($L$2,'DANH SÁCH'!$B$8:$AH$70,23,0)
A34: - Người sử dụng lao động: | D34: =VLOOKUP($L$2,'DANH SÁCH'!$B$8:$AH$70,21,0)
A35: - Đại diện người sử dụng lao động: | E35: =VLOOKUP($L$2,'DANH SÁCH'!$B$8:$AH$70,24,0) | H35: Chức vụ: Giám đốc
A36: - Điện thoại: | B36: =VLOOKUP($L$2,'DANH SÁCH'!$B$8:$AH$70,25,0)
A37: Điều 2: Quyền và nghĩa vụ của người lao động
A38: 2.1.Tham gia đầy đủ khóa học giáo dục định hướng trước khi đi làm việc tại Nhật bản do Bên đưa đi tổ chức; trong thời gian 30 ngày; đảm bảo thời lượng 74 tiết, kiểm tra đạt kết quả và được cấp Giấy chứng nhận hoàn thành khóa học.
A39: 2.2. Tham gia khóa bồi dưỡng kỹ năng nghề do Bên đưa đi tổ chức (nếu có) trong thời gian 30 ngày. Phí bồi dưỡng kỹ năng nghề do Công Ty TNHH Đào Và Cung Ứng Nhân Lực Nhật Tân chi trả.
A40: 2.3. Tham gia khóa đào tạo ngoại ngữ tiếng Nhật do Bên đưa đi tổ chức (nếu có) trong thời gian 180 ngày. Phí đào tạo ngoại ngữ tiếng là 5.900.000 đồng, do người lao động chi trả.
A41: 2.4. Chi phí người lao động phải trả trước khi đi:
A42: - Tiền dịch vụ : | H42: : 40.000.000 VNĐ
A43: + Thời gian nộp (1 lần): Tối thiểu trước xuất cảnh 5 ngày
A44: - Tiền đóng góp Quỹ hỗ trợ việc làm ngoài nước | H44: : 100.000 VNĐ
...
